<?xml version="1.0" ?>
<robot name="partnet_1d4093ad2dfad9df24be2e4f911ee4af">
	<link name="link_0">
		<inertial>
        	<origin xyz="0 0 0.0" rpy="0 0 0"/>
        	<mass value="0.0006"/>
        	<inertia ixx="0.005" ixy="0.0" ixz="0.0" iyy="0.005" iyz="0.0" izz="0.005"/>
		</inertial>
		<visual name="lid-14">
			<origin xyz="-0.0007469999999999994 0 0.0050737480156660434"/>
			<geometry>
				<mesh filename="/home/rohan/Projects/pick_n_place/src/models/urdf/bottle_v1/textured_objs/original-2.obj" scale="0.1 0.1 0.1"/>
			</geometry>
		</visual>
		<collision>
			<origin xyz="-0.0007469999999999994 0 0.0050737480156660434"/>
			<geometry>
				<mesh filename="/home/rohan/Projects/pick_n_place/src/models/urdf/bottle_v1/textured_objs/original-2.obj" scale="0.1 0.1 0.1"/>
			</geometry>
		</collision>
	</link>
	<joint name="joint_0" type="continuous">
		<origin xyz="0.0 0 0.0"/>
		<axis xyz="0 1 0"/>
		<child link="link_0"/>
		<parent link="link_0_helper"/>
	</joint>
	<link name="link_1">
		<inertial>
        	<origin xyz="0 0 0.0" rpy="0 0 0"/>
        	<mass value="0.03"/>
        	<inertia ixx="0.0005" ixy="0.0" ixz="0.0" iyy="0.0005" iyz="0.0" izz="0.0005"/>
		</inertial>
		<visual name="body-12">
			<origin xyz="0 0 0"/>
			<geometry>
				<mesh filename="/home/rohan/Projects/pick_n_place/src/models/urdf/bottle_v1/textured_objs/new-3.obj" scale="0.1 0.1 0.1"/>
			</geometry>
		</visual>
		<visual name="body-12">
			<origin xyz="0 0 0"/>
			<geometry>
				<mesh filename="/home/rohan/Projects/pick_n_place/src/models/urdf/bottle_v1/textured_objs/original-7.obj" scale="0.1 0.1 0.1"/>
			</geometry>
		</visual>
		<visual name="body-12">
			<origin xyz="0 0 0"/>
			<geometry>
				<mesh filename="/home/rohan/Projects/pick_n_place/src/models/urdf/bottle_v1/textured_objs/original-6.obj" scale="0.1 0.1 0.1"/>
			</geometry>
		</visual>
		<visual name="body-12">
			<origin xyz="0 0 0"/>
			<geometry>
				<mesh filename="/home/rohan/Projects/pick_n_place/src/models/urdf/bottle_v1/textured_objs/original-5.obj" scale="0.1 0.1 0.1"/>
			</geometry>
		</visual>
		<visual name="body-12">
			<origin xyz="0 0 0"/>
			<geometry>
				<mesh filename="/home/rohan/Projects/pick_n_place/src/models/urdf/bottle_v1/textured_objs/original-4.obj" scale="0.1 0.1 0.1"/>
			</geometry>
		</visual>
		<visual name="body-12">
			<origin xyz="0 0 0"/>
			<geometry>
				<mesh filename="/home/rohan/Projects/pick_n_place/src/models/urdf/bottle_v1/textured_objs/original-3.obj" scale="0.1 0.1 0.1"/>
			</geometry>
		</visual>
		<visual name="neck-13">
			<origin xyz="0 0 0"/>
			<geometry>
				<mesh filename="/home/rohan/Projects/pick_n_place/src/models/urdf/bottle_v1/textured_objs/new-0.obj" scale="0.1 0.1 0.1"/>
			</geometry>
		</visual>
		<visual name="neck-13">
			<origin xyz="0 0 0"/>
			<geometry>
				<mesh filename="/home/rohan/Projects/pick_n_place/src/models/urdf/bottle_v1/textured_objs/new-1.obj" scale="0.1 0.1 0.1"/>
			</geometry>
		</visual>
		<collision>
			<origin xyz="0 0 0"/>
			<geometry>
				<mesh filename="/home/rohan/Projects/pick_n_place/src/models/urdf/bottle_v1/textured_objs/new-3.obj" scale="0.1 0.1 0.1"/>
			</geometry>
		</collision>
		<collision>
			<origin xyz="0 0 0"/>
			<geometry>
				<mesh filename="/home/rohan/Projects/pick_n_place/src/models/urdf/bottle_v1/textured_objs/original-7.obj" scale="0.1 0.1 0.1"/>
			</geometry>
		</collision>
		<collision>
			<origin xyz="0 0 0"/>
			<geometry>
				<mesh filename="/home/rohan/Projects/pick_n_place/src/models/urdf/bottle_v1/textured_objs/original-6.obj" scale="0.1 0.1 0.1"/>
			</geometry>
		</collision>
		<collision>
			<origin xyz="0 0 0"/>
			<geometry>
				<mesh filename="/home/rohan/Projects/pick_n_place/src/models/urdf/bottle_v1/textured_objs/original-5.obj" scale="0.1 0.1 0.1"/>
			</geometry>
		</collision>
		<collision>
			<origin xyz="0 0 0"/>
			<geometry>
				<mesh filename="/home/rohan/Projects/pick_n_place/src/models/urdf/bottle_v1/textured_objs/original-4.obj" scale="0.1 0.1 0.1"/>
			</geometry>
		</collision>
		<collision>
			<origin xyz="0 0 0"/>
			<geometry>
				<mesh filename="/home/rohan/Projects/pick_n_place/src/models/urdf/bottle_v1/textured_objs/original-3.obj" scale="0.1 0.1 0.1"/>
			</geometry>
		</collision>
		<collision>
			<origin xyz="0 0 0"/>
			<geometry>
				<mesh filename="/home/rohan/Projects/pick_n_place/src/models/urdf/bottle_v1/textured_objs/new-0.obj" scale="0.1 0.1 0.1"/>
			</geometry>
		</collision>
		<collision>
			<origin xyz="0 0 0"/>
			<geometry>
				<mesh filename="/home/rohan/Projects/pick_n_place/src/models/urdf/bottle_v1/textured_objs/new-1.obj" scale="0.1 0.1 0.1"/>
			</geometry>
		</collision>
	</link>
	<link name="link_0_helper"/>
	<joint name="joint_2" type="prismatic">
		<origin xyz="0.0007469999999999994 0 -0.0050737480156660434"/>
		<axis xyz="0 1 0"/>
		<child link="link_0_helper"/>
		<parent link="link_1"/>
		<limit effort="30" velocity="1.0" lower="-0.03200000000000003" upper="0"/>
	</joint>
</robot>
